<?xml version="1.0"?>
<!-- 
    This file is the urdf description of an ALDEBARAN robot.
    It has been generated by robot_description tool available in the simulator-sdk.
    For more information about urdf, see http://www.ros.org/wiki/urdf/
 -->
<robot name="Nao">
  <material name="LightGrey">
    <color rgba="0.9 0.9 0.9 1.0"/>
  </material>
  <link name="TorsoLink">
    <visual>
      <origin xyz="0 0 0" rpy="0 -0 0"/>
      <geometry>
        <mesh filename="file:///opt/Aldebaran/Choregraphe Suite 2.0/share/alrobotmodel/meshes/nao/V32/Torso.mesh" scale="0.001 0.001 0.001"/>
      </geometry>
      <material name="LightGrey"/>
    </visual>
    <inertial>
      <origin xyz="-0.0048 6e-05 0.04227" rpy="0 0 0"/>
      <mass value="1.02628"/>
      <inertia ixx="0.00487953" ixy="1.42859e-05" ixz="0.000195457" iyy="0.00470361" iyz="-2.22459e-05" izz="0.00156714" />
    </inertial>
    <collision>
      <origin xyz="0 0 0" rpy="0 -0 0"/>
      <geometry>
        <mesh filename="file:///opt/Aldebaran/Choregraphe Suite 2.0/share/alrobotmodel/meshes/nao/V32/Torso.mesh" scale="0.001 0.001 0.001"/>
      </geometry>
      <material name="LightGrey"/>
    </collision>
  </link>
  <link name="HeadYawLink">
    <visual>
      <origin xyz="0 0 0" rpy="0 -0 0"/>
      <geometry>
        <mesh filename="file:///opt/Aldebaran/Choregraphe Suite 2.0/share/alrobotmodel/meshes/nao/V32/HeadYaw.mesh" scale="0.001 0.001 0.001"/>
      </geometry>
      <material name="LightGrey"/>
    </visual>
    <inertial>
      <origin xyz="-3e-05 0.00018 -0.02573" rpy="0 0 0"/>
      <mass value="0.05959"/>
      <inertia ixx="6.22337e-05" ixy="-4.2e-10" ixz="-7.448e-08" iyy="6.32443e-05" iyz="-1.0416e-07" izz="5.49462e-06" />
    </inertial>
    <collision>
      <origin xyz="0 0 0" rpy="0 -0 0"/>
      <geometry>
        <mesh filename="file:///opt/Aldebaran/Choregraphe Suite 2.0/share/alrobotmodel/meshes/nao/V32/HeadYaw.mesh" scale="0.001 0.001 0.001"/>
      </geometry>
      <material name="LightGrey"/>
    </collision>
  </link>
  <link name="HeadPitchLink">
    <visual>
      <origin xyz="0 0 0" rpy="0 -0 0"/>
      <geometry>
        <mesh filename="file:///opt/Aldebaran/Choregraphe Suite 2.0/share/alrobotmodel/meshes/nao/V32/HeadPitch.mesh" scale="0.001 0.001 0.001"/>
      </geometry>
      <material name="LightGrey"/>
    </visual>
    <inertial>
      <origin xyz="0.05156 0.00383 -0.00093" rpy="0 0 0"/>
      <mass value="0.47672"/>
      <inertia ixx="0.00487953" ixy="1.42859e-05" ixz="0.000195457" iyy="0.00470361" iyz="-2.22459e-05" izz="0.00156714" />
    </inertial>
    <collision>
      <origin xyz="0 0 0" rpy="0 -0 0"/>
      <geometry>
        <mesh filename="file:///opt/Aldebaran/Choregraphe Suite 2.0/share/alrobotmodel/meshes/nao/V32/HeadPitch.mesh" scale="0.001 0.001 0.001"/>
      </geometry>
      <material name="LightGrey"/>
    </collision>
  </link>
  <link name="LShoulderPitchLink">
    <visual>
      <origin xyz="0 0 0" rpy="0 -0 0"/>
      <geometry>
        <mesh filename="file:///opt/Aldebaran/Choregraphe Suite 2.0/share/alrobotmodel/meshes/nao/V40/LShoulderPitch.mesh" scale="0.001 0.001 0.001"/>
      </geometry>
      <material name="LightGrey"/>
    </visual>
    <inertial>
      <origin xyz="-0.00165 -0.00014 -0.02663" rpy="0 0 0"/>
      <mass value="0.07504"/>
      <inertia ixx="8.42843e-05" ixy="-2.02802e-06" ixz="2.338e-08" iyy="1.41556e-05" iyz="-1.972e-08" izz="8.64195e-05" />
    </inertial>
    <collision>
      <origin xyz="0 0 0" rpy="0 -0 0"/>
      <geometry>
        <mesh filename="file:///opt/Aldebaran/Choregraphe Suite 2.0/share/alrobotmodel/meshes/nao/V40/LShoulderPitch.mesh" scale="0.001 0.001 0.001"/>
      </geometry>
      <material name="LightGrey"/>
    </collision>
  </link>
  <link name="LShoulderRollLink">
    <visual>
      <origin xyz="0 0 0" rpy="0 -0 0"/>
      <geometry>
        <mesh filename="file:///opt/Aldebaran/Choregraphe Suite 2.0/share/alrobotmodel/meshes/nao/V40/LShoulderRoll.mesh" scale="0.001 0.001 0.001"/>
      </geometry>
      <material name="LightGrey"/>
    </visual>
    <inertial>
      <origin xyz="0.00563 -0.02455 0.0033" rpy="0 0 0"/>
      <mass value="0.15777"/>
      <inertia ixx="9.38999e-05" ixy="-4.71445e-05" ixz="-2.69947e-05" iyy="0.000371519" iyz="-2.45977e-06" izz="0.000341901" />
    </inertial>
    <collision>
      <origin xyz="0 0 0" rpy="0 -0 0"/>
      <geometry>
        <mesh filename="file:///opt/Aldebaran/Choregraphe Suite 2.0/share/alrobotmodel/meshes/nao/V40/LShoulderRoll.mesh" scale="0.001 0.001 0.001"/>
      </geometry>
      <material name="LightGrey"/>
    </collision>
  </link>
  <link name="LElbowYawLink">
    <visual>
      <origin xyz="0 0 0" rpy="0 -0 0"/>
      <geometry>
        <mesh filename="file:///opt/Aldebaran/Choregraphe Suite 2.0/share/alrobotmodel/meshes/nao/V40/LElbowYaw.mesh" scale="0.001 0.001 0.001"/>
      </geometry>
      <material name="LightGrey"/>
    </visual>
    <inertial>
      <origin xyz="0 -0.00014 -0.02744" rpy="0 0 0"/>
      <mass value="0.06483"/>
      <inertia ixx="5.59715e-06" ixy="4.21e-09" ixz="4.319e-08" iyy="7.54331e-05" iyz="-1.84e-09" izz="7.64434e-05" />
    </inertial>
    <collision>
      <origin xyz="0 0 0" rpy="0 -0 0"/>
      <geometry>
        <mesh filename="file:///opt/Aldebaran/Choregraphe Suite 2.0/share/alrobotmodel/meshes/nao/V40/LElbowYaw.mesh" scale="0.001 0.001 0.001"/>
      </geometry>
      <material name="LightGrey"/>
    </collision>
  </link>
  <link name="LElbowRollLink">
    <visual>
      <origin xyz="0 0 0" rpy="0 -0 0"/>
      <geometry>
        <mesh filename="file:///opt/Aldebaran/Choregraphe Suite 2.0/share/alrobotmodel/meshes/nao/V40/LElbowRoll.mesh" scale="0.001 0.001 0.001"/>
      </geometry>
      <material name="LightGrey"/>
    </visual>
    <inertial>
      <origin xyz="0.00281 -0.02556 0.00076" rpy="0 0 0"/>
      <mass value="0.07761"/>
      <inertia ixx="2.53322e-05" ixy="-2.34271e-06" ixz="7.459e-08" iyy="8.91322e-05" iyz="-2.655e-08" izz="8.72873e-05" />
    </inertial>
    <collision>
      <origin xyz="0 0 0" rpy="0 -0 0"/>
      <geometry>
        <mesh filename="file:///opt/Aldebaran/Choregraphe Suite 2.0/share/alrobotmodel/meshes/nao/V40/LElbowRoll.mesh" scale="0.001 0.001 0.001"/>
      </geometry>
      <material name="LightGrey"/>
    </collision>
  </link>
  <link name="LWristYawLink">
    <visual>
      <origin xyz="0 0 0" rpy="0 -0 0"/>
      <geometry>
        <mesh filename="file:///opt/Aldebaran/Choregraphe Suite 2.0/share/alrobotmodel/meshes/nao/V40/WristYaw.mesh" scale="0.001 0.001 0.001"/>
      </geometry>
      <material name="LightGrey"/>
    </visual>
    <inertial>
      <origin xyz="-0.00088 0.00308 0.03434" rpy="0 0 0"/>
      <mass value="0.18533"/>
      <inertia ixx="7.05493e-05" ixy="5.71599e-06" ixz="-2.24744e-05" iyy="0.000356062" iyz="3.17771e-06" izz="0.000351919" />
    </inertial>
    <collision>
      <origin xyz="0 0 0" rpy="0 -0 0"/>
      <geometry>
        <mesh filename="file:///opt/Aldebaran/Choregraphe Suite 2.0/share/alrobotmodel/meshes/nao/V40/WristYaw.mesh" scale="0.001 0.001 0.001"/>
      </geometry>
      <material name="LightGrey"/>
    </collision>
  </link>
  <link name="LFinger11Link">
    <visual>
      <origin xyz="0 0 0" rpy="0 -0 0"/>
      <geometry>
        <mesh filename="file:///opt/Aldebaran/Choregraphe Suite 2.0/share/alrobotmodel/meshes/nao/Phalax.mesh" scale="0.001 0.001 0.001"/>
      </geometry>
      <material name="LightGrey"/>
    </visual>
    <inertial>
      <origin xyz="0 0 0" rpy="0 0 0"/>
      <mass value="0"/>
      <inertia ixx="0" ixy="0" ixz="0" iyy="0" iyz="0" izz="0" />
    </inertial>
    <collision>
      <origin xyz="0 0 0" rpy="0 -0 0"/>
      <geometry>
        <mesh filename="file:///opt/Aldebaran/Choregraphe Suite 2.0/share/alrobotmodel/meshes/nao/Phalax.mesh" scale="0.001 0.001 0.001"/>
      </geometry>
      <material name="LightGrey"/>
    </collision>
  </link>
  <link name="LFinger12Link">
    <visual>
      <origin xyz="0 0 0" rpy="0 -0 0"/>
      <geometry>
        <mesh filename="file:///opt/Aldebaran/Choregraphe Suite 2.0/share/alrobotmodel/meshes/nao/Phalax.mesh" scale="0.001 0.001 0.001"/>
      </geometry>
      <material name="LightGrey"/>
    </visual>
    <inertial>
      <origin xyz="0 0 0" rpy="0 0 0"/>
      <mass value="0"/>
      <inertia ixx="0" ixy="0" ixz="0" iyy="0" iyz="0" izz="0" />
    </inertial>
    <collision>
      <origin xyz="0 0 0" rpy="0 -0 0"/>
      <geometry>
        <mesh filename="file:///opt/Aldebaran/Choregraphe Suite 2.0/share/alrobotmodel/meshes/nao/Phalax.mesh" scale="0.001 0.001 0.001"/>
      </geometry>
      <material name="LightGrey"/>
    </collision>
  </link>
  <link name="LFinger13Link">
    <visual>
      <origin xyz="0 0 0" rpy="0 -0 0"/>
      <geometry>
        <mesh filename="file:///opt/Aldebaran/Choregraphe Suite 2.0/share/alrobotmodel/meshes/nao/PhalaxEnd.mesh" scale="0.001 0.001 0.001"/>
      </geometry>
      <material name="LightGrey"/>
    </visual>
    <inertial>
      <origin xyz="0 0 0" rpy="0 0 0"/>
      <mass value="0"/>
      <inertia ixx="0" ixy="0" ixz="0" iyy="0" iyz="0" izz="0" />
    </inertial>
    <collision>
      <origin xyz="0 0 0" rpy="0 -0 0"/>
      <geometry>
        <mesh filename="file:///opt/Aldebaran/Choregraphe Suite 2.0/share/alrobotmodel/meshes/nao/PhalaxEnd.mesh" scale="0.001 0.001 0.001"/>
      </geometry>
      <material name="LightGrey"/>
    </collision>
  </link>
  <link name="LFinger21Link">
    <visual>
      <origin xyz="0 0 0" rpy="0 -0 0"/>
      <geometry>
        <mesh filename="file:///opt/Aldebaran/Choregraphe Suite 2.0/share/alrobotmodel/meshes/nao/Phalax.mesh" scale="0.001 0.001 0.001"/>
      </geometry>
      <material name="LightGrey"/>
    </visual>
    <inertial>
      <origin xyz="0 0 0" rpy="0 0 0"/>
      <mass value="0"/>
      <inertia ixx="0" ixy="0" ixz="0" iyy="0" iyz="0" izz="0" />
    </inertial>
    <collision>
      <origin xyz="0 0 0" rpy="0 -0 0"/>
      <geometry>
        <mesh filename="file:///opt/Aldebaran/Choregraphe Suite 2.0/share/alrobotmodel/meshes/nao/Phalax.mesh" scale="0.001 0.001 0.001"/>
      </geometry>
      <material name="LightGrey"/>
    </collision>
  </link>
  <link name="LFinger22Link">
    <visual>
      <origin xyz="0 0 0" rpy="0 -0 0"/>
      <geometry>
        <mesh filename="file:///opt/Aldebaran/Choregraphe Suite 2.0/share/alrobotmodel/meshes/nao/Phalax.mesh" scale="0.001 0.001 0.001"/>
      </geometry>
      <material name="LightGrey"/>
    </visual>
    <inertial>
      <origin xyz="0 0 0" rpy="0 0 0"/>
      <mass value="0"/>
      <inertia ixx="0" ixy="0" ixz="0" iyy="0" iyz="0" izz="0" />
    </inertial>
    <collision>
      <origin xyz="0 0 0" rpy="0 -0 0"/>
      <geometry>
        <mesh filename="file:///opt/Aldebaran/Choregraphe Suite 2.0/share/alrobotmodel/meshes/nao/Phalax.mesh" scale="0.001 0.001 0.001"/>
      </geometry>
      <material name="LightGrey"/>
    </collision>
  </link>
  <link name="LFinger23Link">
    <visual>
      <origin xyz="0 0 0" rpy="0 -0 0"/>
      <geometry>
        <mesh filename="file:///opt/Aldebaran/Choregraphe Suite 2.0/share/alrobotmodel/meshes/nao/PhalaxEnd.mesh" scale="0.001 0.001 0.001"/>
      </geometry>
      <material name="LightGrey"/>
    </visual>
    <inertial>
      <origin xyz="0 0 0" rpy="0 0 0"/>
      <mass value="0"/>
      <inertia ixx="0" ixy="0" ixz="0" iyy="0" iyz="0" izz="0" />
    </inertial>
    <collision>
      <origin xyz="0 0 0" rpy="0 -0 0"/>
      <geometry>
        <mesh filename="file:///opt/Aldebaran/Choregraphe Suite 2.0/share/alrobotmodel/meshes/nao/PhalaxEnd.mesh" scale="0.001 0.001 0.001"/>
      </geometry>
      <material name="LightGrey"/>
    </collision>
  </link>
  <link name="LThumb1Link">
    <visual>
      <origin xyz="0 0 0" rpy="0 -0 0"/>
      <geometry>
        <mesh filename="file:///opt/Aldebaran/Choregraphe Suite 2.0/share/alrobotmodel/meshes/nao/Phalax.mesh" scale="0.001 0.001 0.001"/>
      </geometry>
      <material name="LightGrey"/>
    </visual>
    <inertial>
      <origin xyz="0 0 0" rpy="0 0 0"/>
      <mass value="0"/>
      <inertia ixx="0" ixy="0" ixz="0" iyy="0" iyz="0" izz="0" />
    </inertial>
    <collision>
      <origin xyz="0 0 0" rpy="0 -0 0"/>
      <geometry>
        <mesh filename="file:///opt/Aldebaran/Choregraphe Suite 2.0/share/alrobotmodel/meshes/nao/Phalax.mesh" scale="0.001 0.001 0.001"/>
      </geometry>
      <material name="LightGrey"/>
    </collision>
  </link>
  <link name="LThumb2Link">
    <visual>
      <origin xyz="0 0 0" rpy="0 -0 0"/>
      <geometry>
        <mesh filename="file:///opt/Aldebaran/Choregraphe Suite 2.0/share/alrobotmodel/meshes/nao/PhalaxEnd.mesh" scale="0.001 0.001 0.001"/>
      </geometry>
      <material name="LightGrey"/>
    </visual>
    <inertial>
      <origin xyz="0 0 0" rpy="0 0 0"/>
      <mass value="0"/>
      <inertia ixx="0" ixy="0" ixz="0" iyy="0" iyz="0" izz="0" />
    </inertial>
    <collision>
      <origin xyz="0 0 0" rpy="0 -0 0"/>
      <geometry>
        <mesh filename="file:///opt/Aldebaran/Choregraphe Suite 2.0/share/alrobotmodel/meshes/nao/PhalaxEnd.mesh" scale="0.001 0.001 0.001"/>
      </geometry>
      <material name="LightGrey"/>
    </collision>
  </link>
  <link name="RShoulderPitchLink">
    <visual>
      <origin xyz="0 0 0" rpy="0 -0 0"/>
      <geometry>
        <mesh filename="file:///opt/Aldebaran/Choregraphe Suite 2.0/share/alrobotmodel/meshes/nao/V40/RShoulderPitch.mesh" scale="0.001 0.001 0.001"/>
      </geometry>
      <material name="LightGrey"/>
    </visual>
    <inertial>
      <origin xyz="-0.00165 -0.00014 0.02663" rpy="0 0 0"/>
      <mass value="0.07504"/>
      <inertia ixx="8.42843e-05" ixy="2.02802e-06" ixz="2.338e-08" iyy="1.41556e-05" iyz="1.972e-08" izz="8.64195e-05" />
    </inertial>
    <collision>
      <origin xyz="0 0 0" rpy="0 -0 0"/>
      <geometry>
        <mesh filename="file:///opt/Aldebaran/Choregraphe Suite 2.0/share/alrobotmodel/meshes/nao/V40/RShoulderPitch.mesh" scale="0.001 0.001 0.001"/>
      </geometry>
      <material name="LightGrey"/>
    </collision>
  </link>
  <link name="RShoulderRollLink">
    <visual>
      <origin xyz="0 0 0" rpy="0 -0 0"/>
      <geometry>
        <mesh filename="file:///opt/Aldebaran/Choregraphe Suite 2.0/share/alrobotmodel/meshes/nao/V40/RShoulderRoll.mesh" scale="0.001 0.001 0.001"/>
      </geometry>
      <material name="LightGrey"/>
    </visual>
    <inertial>
      <origin xyz="-0.00952 -0.02429 0.0032" rpy="0 0 0"/>
      <mass value="0.15794"/>
      <inertia ixx="0.00011012" ixy="7.66913e-05" ixz="-2.60461e-05" iyy="0.000367577" iyz="1.20983e-05" izz="0.000354618" />
    </inertial>
    <collision>
      <origin xyz="0 0 0" rpy="0 -0 0"/>
      <geometry>
        <mesh filename="file:///opt/Aldebaran/Choregraphe Suite 2.0/share/alrobotmodel/meshes/nao/V40/RShoulderRoll.mesh" scale="0.001 0.001 0.001"/>
      </geometry>
      <material name="LightGrey"/>
    </collision>
  </link>
  <link name="RElbowRollLink">
    <visual>
      <origin xyz="0 0 0" rpy="0 -0 0"/>
      <geometry>
        <mesh filename="file:///opt/Aldebaran/Choregraphe Suite 2.0/share/alrobotmodel/meshes/nao/V40/RElbowRoll.mesh" scale="0.001 0.001 0.001"/>
      </geometry>
      <material name="LightGrey"/>
    </visual>
    <inertial>
      <origin xyz="-0.00281 -0.02552 0.0009" rpy="0 0 0"/>
      <mass value="0.07778"/>
      <inertia ixx="2.53907e-05" ixy="2.33243e-06" ixz="-6.0117e-07" iyy="8.92204e-05" iyz="2.694e-08" izz="8.72484e-05" />
    </inertial>
    <collision>
      <origin xyz="0 0 0" rpy="0 -0 0"/>
      <geometry>
        <mesh filename="file:///opt/Aldebaran/Choregraphe Suite 2.0/share/alrobotmodel/meshes/nao/V40/RElbowRoll.mesh" scale="0.001 0.001 0.001"/>
      </geometry>
      <material name="LightGrey"/>
    </collision>
  </link>
  <link name="RWristYawLink">
    <visual>
      <origin xyz="0 0 0" rpy="0 -0 0"/>
      <geometry>
        <mesh filename="file:///opt/Aldebaran/Choregraphe Suite 2.0/share/alrobotmodel/meshes/nao/V40/WristYaw.mesh" scale="0.001 0.001 0.001"/>
      </geometry>
      <material name="LightGrey"/>
    </visual>
    <inertial>
      <origin xyz="-0.00088 0.00308 0.03434" rpy="0 0 0"/>
      <mass value="0.18533"/>
      <inertia ixx="7.05493e-05" ixy="5.71599e-06" ixz="-2.24744e-05" iyy="0.000356062" iyz="3.17771e-06" izz="0.000351919" />
    </inertial>
    <collision>
      <origin xyz="0 0 0" rpy="0 -0 0"/>
      <geometry>
        <mesh filename="file:///opt/Aldebaran/Choregraphe Suite 2.0/share/alrobotmodel/meshes/nao/V40/WristYaw.mesh" scale="0.001 0.001 0.001"/>
      </geometry>
      <material name="LightGrey"/>
    </collision>
  </link>
  <link name="RFinger11Link">
    <visual>
      <origin xyz="0 0 0" rpy="0 -0 0"/>
      <geometry>
        <mesh filename="file:///opt/Aldebaran/Choregraphe Suite 2.0/share/alrobotmodel/meshes/nao/Phalax.mesh" scale="0.001 0.001 0.001"/>
      </geometry>
      <material name="LightGrey"/>
    </visual>
    <inertial>
      <origin xyz="0 0 0" rpy="0 0 0"/>
      <mass value="0"/>
      <inertia ixx="0" ixy="0" ixz="0" iyy="0" iyz="0" izz="0" />
    </inertial>
    <collision>
      <origin xyz="0 0 0" rpy="0 -0 0"/>
      <geometry>
        <mesh filename="file:///opt/Aldebaran/Choregraphe Suite 2.0/share/alrobotmodel/meshes/nao/Phalax.mesh" scale="0.001 0.001 0.001"/>
      </geometry>
      <material name="LightGrey"/>
    </collision>
  </link>
  <link name="RFinger12Link">
    <visual>
      <origin xyz="0 0 0" rpy="0 -0 0"/>
      <geometry>
        <mesh filename="file:///opt/Aldebaran/Choregraphe Suite 2.0/share/alrobotmodel/meshes/nao/Phalax.mesh" scale="0.001 0.001 0.001"/>
      </geometry>
      <material name="LightGrey"/>
    </visual>
    <inertial>
      <origin xyz="0 0 0" rpy="0 0 0"/>
      <mass value="0"/>
      <inertia ixx="0" ixy="0" ixz="0" iyy="0" iyz="0" izz="0" />
    </inertial>
    <collision>
      <origin xyz="0 0 0" rpy="0 -0 0"/>
      <geometry>
        <mesh filename="file:///opt/Aldebaran/Choregraphe Suite 2.0/share/alrobotmodel/meshes/nao/Phalax.mesh" scale="0.001 0.001 0.001"/>
      </geometry>
      <material name="LightGrey"/>
    </collision>
  </link>
  <link name="RFinger13Link">
    <visual>
      <origin xyz="0 0 0" rpy="0 -0 0"/>
      <geometry>
        <mesh filename="file:///opt/Aldebaran/Choregraphe Suite 2.0/share/alrobotmodel/meshes/nao/PhalaxEnd.mesh" scale="0.001 0.001 0.001"/>
      </geometry>
      <material name="LightGrey"/>
    </visual>
    <inertial>
      <origin xyz="0 0 0" rpy="0 0 0"/>
      <mass value="0"/>
      <inertia ixx="0" ixy="0" ixz="0" iyy="0" iyz="0" izz="0" />
    </inertial>
    <collision>
      <origin xyz="0 0 0" rpy="0 -0 0"/>
      <geometry>
        <mesh filename="file:///opt/Aldebaran/Choregraphe Suite 2.0/share/alrobotmodel/meshes/nao/PhalaxEnd.mesh" scale="0.001 0.001 0.001"/>
      </geometry>
      <material name="LightGrey"/>
    </collision>
  </link>
  <link name="RFinger21Link">
    <visual>
      <origin xyz="0 0 0" rpy="0 -0 0"/>
      <geometry>
        <mesh filename="file:///opt/Aldebaran/Choregraphe Suite 2.0/share/alrobotmodel/meshes/nao/Phalax.mesh" scale="0.001 0.001 0.001"/>
      </geometry>
      <material name="LightGrey"/>
    </visual>
    <inertial>
      <origin xyz="0 0 0" rpy="0 0 0"/>
      <mass value="0"/>
      <inertia ixx="0" ixy="0" ixz="0" iyy="0" iyz="0" izz="0" />
    </inertial>
    <collision>
      <origin xyz="0 0 0" rpy="0 -0 0"/>
      <geometry>
        <mesh filename="file:///opt/Aldebaran/Choregraphe Suite 2.0/share/alrobotmodel/meshes/nao/Phalax.mesh" scale="0.001 0.001 0.001"/>
      </geometry>
      <material name="LightGrey"/>
    </collision>
  </link>
  <link name="RFinger22Link">
    <visual>
      <origin xyz="0 0 0" rpy="0 -0 0"/>
      <geometry>
        <mesh filename="file:///opt/Aldebaran/Choregraphe Suite 2.0/share/alrobotmodel/meshes/nao/Phalax.mesh" scale="0.001 0.001 0.001"/>
      </geometry>
      <material name="LightGrey"/>
    </visual>
    <inertial>
      <origin xyz="0 0 0" rpy="0 0 0"/>
      <mass value="0"/>
      <inertia ixx="0" ixy="0" ixz="0" iyy="0" iyz="0" izz="0" />
    </inertial>
    <collision>
      <origin xyz="0 0 0" rpy="0 -0 0"/>
      <geometry>
        <mesh filename="file:///opt/Aldebaran/Choregraphe Suite 2.0/share/alrobotmodel/meshes/nao/Phalax.mesh" scale="0.001 0.001 0.001"/>
      </geometry>
      <material name="LightGrey"/>
    </collision>
  </link>
  <link name="RFinger23Link">
    <visual>
      <origin xyz="0 0 0" rpy="0 -0 0"/>
      <geometry>
        <mesh filename="file:///opt/Aldebaran/Choregraphe Suite 2.0/share/alrobotmodel/meshes/nao/PhalaxEnd.mesh" scale="0.001 0.001 0.001"/>
      </geometry>
      <material name="LightGrey"/>
    </visual>
    <inertial>
      <origin xyz="0 0 0" rpy="0 0 0"/>
      <mass value="0"/>
      <inertia ixx="0" ixy="0" ixz="0" iyy="0" iyz="0" izz="0" />
    </inertial>
    <collision>
      <origin xyz="0 0 0" rpy="0 -0 0"/>
      <geometry>
        <mesh filename="file:///opt/Aldebaran/Choregraphe Suite 2.0/share/alrobotmodel/meshes/nao/PhalaxEnd.mesh" scale="0.001 0.001 0.001"/>
      </geometry>
      <material name="LightGrey"/>
    </collision>
  </link>
  <link name="RThumb1Link">
    <visual>
      <origin xyz="0 0 0" rpy="0 -0 0"/>
      <geometry>
        <mesh filename="file:///opt/Aldebaran/Choregraphe Suite 2.0/share/alrobotmodel/meshes/nao/Phalax.mesh" scale="0.001 0.001 0.001"/>
      </geometry>
      <material name="LightGrey"/>
    </visual>
    <inertial>
      <origin xyz="0 0 0" rpy="0 0 0"/>
      <mass value="0"/>
      <inertia ixx="0" ixy="0" ixz="0" iyy="0" iyz="0" izz="0" />
    </inertial>
    <collision>
      <origin xyz="0 0 0" rpy="0 -0 0"/>
      <geometry>
        <mesh filename="file:///opt/Aldebaran/Choregraphe Suite 2.0/share/alrobotmodel/meshes/nao/Phalax.mesh" scale="0.001 0.001 0.001"/>
      </geometry>
      <material name="LightGrey"/>
    </collision>
  </link>
  <link name="RThumb2Link">
    <visual>
      <origin xyz="0 0 0" rpy="0 -0 0"/>
      <geometry>
        <mesh filename="file:///opt/Aldebaran/Choregraphe Suite 2.0/share/alrobotmodel/meshes/nao/PhalaxEnd.mesh" scale="0.001 0.001 0.001"/>
      </geometry>
      <material name="LightGrey"/>
    </visual>
    <inertial>
      <origin xyz="0 0 0" rpy="0 0 0"/>
      <mass value="0"/>
      <inertia ixx="0" ixy="0" ixz="0" iyy="0" iyz="0" izz="0" />
    </inertial>
    <collision>
      <origin xyz="0 0 0" rpy="0 -0 0"/>
      <geometry>
        <mesh filename="file:///opt/Aldebaran/Choregraphe Suite 2.0/share/alrobotmodel/meshes/nao/PhalaxEnd.mesh" scale="0.001 0.001 0.001"/>
      </geometry>
      <material name="LightGrey"/>
    </collision>
  </link>
  <link name="LHipYawPitchLink">
    <visual>
      <origin xyz="0 0 0" rpy="0 -0 0"/>
      <geometry>
        <mesh filename="file:///opt/Aldebaran/Choregraphe Suite 2.0/share/alrobotmodel/meshes/nao/V32/LHipYawPitch.mesh" scale="0.001 0.001 0.001"/>
      </geometry>
      <material name="LightGrey"/>
    </visual>
    <inertial>
      <origin xyz="0.0107339 -0.00717 -0.0275206" rpy="0 0 0"/>
      <mass value="0.07244"/>
      <inertia ixx="9.06449e-05" ixy="-4.88819e-06" ixz="1.22192e-05" iyy="0.000106658" iyz="2.78382e-05" izz="6.74286e-05" />
    </inertial>
    <collision>
      <origin xyz="0 0 0" rpy="0 -0 0"/>
      <geometry>
        <mesh filename="file:///opt/Aldebaran/Choregraphe Suite 2.0/share/alrobotmodel/meshes/nao/V32/LHipYawPitch.mesh" scale="0.001 0.001 0.001"/>
      </geometry>
      <material name="LightGrey"/>
    </collision>
  </link>
  <link name="LHipRollLink">
    <visual>
      <origin xyz="0 0 0" rpy="0 -0 0"/>
      <geometry>
        <mesh filename="file:///opt/Aldebaran/Choregraphe Suite 2.0/share/alrobotmodel/meshes/nao/V32/LHipRoll.mesh" scale="0.001 0.001 0.001"/>
      </geometry>
      <material name="LightGrey"/>
    </visual>
    <inertial>
      <origin xyz="-0.00475 -0.00029 -0.01649" rpy="0 0 0"/>
      <mass value="0.1353"/>
      <inertia ixx="2.79131e-05" ixy="4.982e-08" ixz="-5.30968e-06" iyy="0.000101469" iyz="4.9e-10" izz="0.000292094" />
    </inertial>
    <collision>
      <origin xyz="0 0 0" rpy="0 -0 0"/>
      <geometry>
        <mesh filename="file:///opt/Aldebaran/Choregraphe Suite 2.0/share/alrobotmodel/meshes/nao/V32/LHipRoll.mesh" scale="0.001 0.001 0.001"/>
      </geometry>
      <material name="LightGrey"/>
    </collision>
  </link>
  <link name="LHipPitchLink">
    <visual>
      <origin xyz="0 0 0" rpy="0 -0 0"/>
      <geometry>
        <mesh filename="file:///opt/Aldebaran/Choregraphe Suite 2.0/share/alrobotmodel/meshes/nao/V32/LHipPitch.mesh" scale="0.001 0.001 0.001"/>
      </geometry>
      <material name="LightGrey"/>
    </visual>
    <inertial>
      <origin xyz="-0.05386 0.00131 0.00201" rpy="0 0 0"/>
      <mass value="0.39798"/>
      <inertia ixx="0.00166559" ixy="4.3251e-07" ixz="8.25051e-05" iyy="0.001625" iyz="3.17428e-05" izz="0.000304929" />
    </inertial>
    <collision>
      <origin xyz="0 0 0" rpy="0 -0 0"/>
      <geometry>
        <mesh filename="file:///opt/Aldebaran/Choregraphe Suite 2.0/share/alrobotmodel/meshes/nao/V32/LHipPitch.mesh" scale="0.001 0.001 0.001"/>
      </geometry>
      <material name="LightGrey"/>
    </collision>
  </link>
  <link name="LKneePitchLink">
    <visual>
      <origin xyz="0 0 0" rpy="0 -0 0"/>
      <geometry>
        <mesh filename="file:///opt/Aldebaran/Choregraphe Suite 2.0/share/alrobotmodel/meshes/nao/V32/LKneePitch.mesh" scale="0.001 0.001 0.001"/>
      </geometry>
      <material name="LightGrey"/>
    </visual>
    <inertial>
      <origin xyz="-0.04891 0.00471 0.0021" rpy="0 0 0"/>
      <mass value="0.29714"/>
      <inertia ixx="0.00118034" ixy="3.0542e-07" ixz="4.0171e-05" iyy="0.00112928" iyz="3.57364e-05" izz="0.00019349" />
    </inertial>
    <collision>
      <origin xyz="0 0 0" rpy="0 -0 0"/>
      <geometry>
        <mesh filename="file:///opt/Aldebaran/Choregraphe Suite 2.0/share/alrobotmodel/meshes/nao/V32/LKneePitch.mesh" scale="0.001 0.001 0.001"/>
      </geometry>
      <material name="LightGrey"/>
    </collision>
  </link>
  <link name="LAnklePitchLink">
    <visual>
      <origin xyz="0 0 0" rpy="0 -0 0"/>
      <geometry>
        <mesh filename="file:///opt/Aldebaran/Choregraphe Suite 2.0/share/alrobotmodel/meshes/nao/V32/LAnklePitch.mesh" scale="0.001 0.001 0.001"/>
      </geometry>
      <material name="LightGrey"/>
    </visual>
    <inertial>
      <origin xyz="0.00638 0.00142 0.00028" rpy="0 0 0"/>
      <mass value="0.13892"/>
      <inertia ixx="3.88258e-05" ixy="-4.942e-08" ixz="2.21321e-06" iyy="7.21158e-05" iyz="6.74e-09" izz="5.35199e-05" />
    </inertial>
    <collision>
      <origin xyz="0 0 0" rpy="0 -0 0"/>
      <geometry>
        <mesh filename="file:///opt/Aldebaran/Choregraphe Suite 2.0/share/alrobotmodel/meshes/nao/V32/LAnklePitch.mesh" scale="0.001 0.001 0.001"/>
      </geometry>
      <material name="LightGrey"/>
    </collision>
  </link>
  <link name="LAnkleRollLink">
    <visual>
      <origin xyz="0 0 0" rpy="0 -0 0"/>
      <geometry>
        <mesh filename="file:///opt/Aldebaran/Choregraphe Suite 2.0/share/alrobotmodel/meshes/nao/V32/LAnkleRoll.mesh" scale="0.001 0.001 0.001"/>
      </geometry>
      <material name="LightGrey"/>
    </visual>
    <inertial>
      <origin xyz="-0.03208 -0.0033 0.02489" rpy="0 0 0"/>
      <mass value="0.16304"/>
      <inertia ixx="0.000267598" ixy="-5.92718e-06" ixz="0.000137299" iyy="0.000643148" iyz="1.86977e-05" izz="0.000526497" />
    </inertial>
    <collision>
      <origin xyz="0 0 0" rpy="0 -0 0"/>
      <geometry>
        <mesh filename="file:///opt/Aldebaran/Choregraphe Suite 2.0/share/alrobotmodel/meshes/nao/V32/LAnkleRoll.mesh" scale="0.001 0.001 0.001"/>
      </geometry>
      <material name="LightGrey"/>
    </collision>
  </link>
  <link name="RHipYawPitchLink">
    <visual>
      <origin xyz="0 0 0" rpy="0 -0 0"/>
      <geometry>
        <mesh filename="file:///opt/Aldebaran/Choregraphe Suite 2.0/share/alrobotmodel/meshes/nao/V32/RHipYawPitch.mesh" scale="0.001 0.001 0.001"/>
      </geometry>
      <material name="LightGrey"/>
    </visual>
    <inertial>
      <origin xyz="0.0107339 -0.00717 0.0275206" rpy="0 0 0"/>
      <mass value="0.07244"/>
      <inertia ixx="9.06449e-05" ixy="4.88819e-06" ixz="1.22192e-05" iyy="0.000106658" iyz="-2.78382e-05" izz="6.74286e-05" />
    </inertial>
    <collision>
      <origin xyz="0 0 0" rpy="0 -0 0"/>
      <geometry>
        <mesh filename="file:///opt/Aldebaran/Choregraphe Suite 2.0/share/alrobotmodel/meshes/nao/V32/RHipYawPitch.mesh" scale="0.001 0.001 0.001"/>
      </geometry>
      <material name="LightGrey"/>
    </collision>
  </link>
  <link name="RHipRollLink">
    <visual>
      <origin xyz="0 0 0" rpy="0 -0 0"/>
      <geometry>
        <mesh filename="file:///opt/Aldebaran/Choregraphe Suite 2.0/share/alrobotmodel/meshes/nao/V32/RHipRoll.mesh" scale="0.001 0.001 0.001"/>
      </geometry>
      <material name="LightGrey"/>
    </visual>
    <inertial>
      <origin xyz="-0.00475 0.00029 -0.01649" rpy="0 0 0"/>
      <mass value="0.1353"/>
      <inertia ixx="2.79131e-05" ixy="-4.982e-08" ixz="-5.30968e-06" iyy="0.000101469" iyz="-4.9e-10" izz="0.000292094" />
    </inertial>
    <collision>
      <origin xyz="0 0 0" rpy="0 -0 0"/>
      <geometry>
        <mesh filename="file:///opt/Aldebaran/Choregraphe Suite 2.0/share/alrobotmodel/meshes/nao/V32/RHipRoll.mesh" scale="0.001 0.001 0.001"/>
      </geometry>
      <material name="LightGrey"/>
    </collision>
  </link>
  <link name="RHipPitchLink">
    <visual>
      <origin xyz="0 0 0" rpy="0 -0 0"/>
      <geometry>
        <mesh filename="file:///opt/Aldebaran/Choregraphe Suite 2.0/share/alrobotmodel/meshes/nao/V32/RHipPitch.mesh" scale="0.001 0.001 0.001"/>
      </geometry>
      <material name="LightGrey"/>
    </visual>
    <inertial>
      <origin xyz="-0.05386 0.00131 -0.00201" rpy="0 0 0"/>
      <mass value="0.39798"/>
      <inertia ixx="0.00166559" ixy="-4.3251e-07" ixz="8.25051e-05" iyy="0.001625" iyz="-3.17428e-05" izz="0.000304929" />
    </inertial>
    <collision>
      <origin xyz="0 0 0" rpy="0 -0 0"/>
      <geometry>
        <mesh filename="file:///opt/Aldebaran/Choregraphe Suite 2.0/share/alrobotmodel/meshes/nao/V32/RHipPitch.mesh" scale="0.001 0.001 0.001"/>
      </geometry>
      <material name="LightGrey"/>
    </collision>
  </link>
  <link name="RKneePitchLink">
    <visual>
      <origin xyz="0 0 0" rpy="0 -0 0"/>
      <geometry>
        <mesh filename="file:///opt/Aldebaran/Choregraphe Suite 2.0/share/alrobotmodel/meshes/nao/V32/RKneePitch.mesh" scale="0.001 0.001 0.001"/>
      </geometry>
      <material name="LightGrey"/>
    </visual>
    <inertial>
      <origin xyz="-0.04891 0.00471 -0.0021" rpy="0 0 0"/>
      <mass value="0.29714"/>
      <inertia ixx="0.00118034" ixy="-3.0542e-07" ixz="4.0171e-05" iyy="0.00112928" iyz="-3.57364e-05" izz="0.00019349" />
    </inertial>
    <collision>
      <origin xyz="0 0 0" rpy="0 -0 0"/>
      <geometry>
        <mesh filename="file:///opt/Aldebaran/Choregraphe Suite 2.0/share/alrobotmodel/meshes/nao/V32/RKneePitch.mesh" scale="0.001 0.001 0.001"/>
      </geometry>
      <material name="LightGrey"/>
    </collision>
  </link>
  <link name="RAnklePitchLink">
    <visual>
      <origin xyz="0 0 0" rpy="0 -0 0"/>
      <geometry>
        <mesh filename="file:///opt/Aldebaran/Choregraphe Suite 2.0/share/alrobotmodel/meshes/nao/V32/RAnklePitch.mesh" scale="0.001 0.001 0.001"/>
      </geometry>
      <material name="LightGrey"/>
    </visual>
    <inertial>
      <origin xyz="0.00638 0.00142 -0.00028" rpy="0 0 0"/>
      <mass value="0.13892"/>
      <inertia ixx="3.88258e-05" ixy="4.942e-08" ixz="2.21321e-06" iyy="7.21158e-05" iyz="-6.74e-09" izz="5.35199e-05" />
    </inertial>
    <collision>
      <origin xyz="0 0 0" rpy="0 -0 0"/>
      <geometry>
        <mesh filename="file:///opt/Aldebaran/Choregraphe Suite 2.0/share/alrobotmodel/meshes/nao/V32/RAnklePitch.mesh" scale="0.001 0.001 0.001"/>
      </geometry>
      <material name="LightGrey"/>
    </collision>
  </link>
  <link name="RAnkleRollLink">
    <visual>
      <origin xyz="0 0 0" rpy="0 -0 0"/>
      <geometry>
        <mesh filename="file:///opt/Aldebaran/Choregraphe Suite 2.0/share/alrobotmodel/meshes/nao/V32/RAnkleRoll.mesh" scale="0.001 0.001 0.001"/>
      </geometry>
      <material name="LightGrey"/>
    </visual>
    <inertial>
      <origin xyz="-0.03208 0.0033 0.02489" rpy="0 0 0"/>
      <mass value="0.16304"/>
      <inertia ixx="0.000267598" ixy="5.92718e-06" ixz="1.37299e-05" iyy="0.000643148" iyz="-1.86977e-05" izz="0.000526497" />
    </inertial>
    <collision>
      <origin xyz="0 0 0" rpy="0 -0 0"/>
      <geometry>
        <mesh filename="file:///opt/Aldebaran/Choregraphe Suite 2.0/share/alrobotmodel/meshes/nao/V32/RAnkleRoll.mesh" scale="0.001 0.001 0.001"/>
      </geometry>
      <material name="LightGrey"/>
    </collision>
  </link>

  <joint name="HeadYaw" type="continuous">
    <parent link="TorsoLink"/>
    <child link="HeadYawLink"/>
    <origin xyz="0 0 0.1265" rpy="0 -0 0"/>
    <axis xyz="0 0 1"/>
  </joint>
  <joint name="HeadPitch" type="continuous">
    <parent link="HeadYawLink"/>
    <child link="HeadPitchLink"/>
    <origin xyz="0 0 0" rpy="0 -0 0"/>
    <axis xyz="0 1 0"/>
  </joint>
  <joint name="LShoulderPitch" type="continuous">
    <parent link="TorsoLink"/>
    <child link="LShoulderPitchLink"/>
    <origin xyz="0 0.098 0.1" rpy="0 -0 0"/>
    <axis xyz="0 1 0"/>
  </joint>
  <joint name="LShoulderRoll" type="continuous">
    <parent link="LShoulderPitchLink"/>
    <child link="LShoulderRollLink"/>
    <origin xyz="0 0 0" rpy="0 -0 0"/>
    <axis xyz="0 0 1"/>
  </joint>
  <joint name="LElbowYaw" type="continuous">
    <parent link="LShoulderRollLink"/>
    <child link="LElbowYawLink"/>
    <origin xyz="0.105 0.015 0" rpy="0 -0 0"/>
    <axis xyz="1 0 0"/>
  </joint>
  <joint name="LElbowRoll" type="continuous">
    <parent link="LElbowYawLink"/>
    <child link="LElbowRollLink"/>
    <origin xyz="0 0 0" rpy="0 -0 0"/>
    <axis xyz="0 0 1"/>
  </joint>
  <joint name="LWristYaw" type="continuous">
    <parent link="LElbowRollLink"/>
    <child link="LWristYawLink"/>
    <origin xyz="0.05595 0 0" rpy="0 -0 0"/>
    <axis xyz="1 0 0"/>
  </joint>
  <joint name="LFinger11" type="continuous">
    <parent link="LWristYawLink"/>
    <child link="LFinger11Link"/>
    <origin xyz="0.06907 0.01157 -0.00304" rpy="0.315405 0.976662 0.264067"/>
    <axis xyz="0 -0.984808 -0.173648"/>
  </joint>
  <joint name="LFinger12" type="continuous">
    <parent link="LFinger11Link"/>
    <child link="LFinger12Link"/>
    <origin xyz="0.01436 0 0" rpy="3.71776e-08 0.999899 6.80614e-08"/>
    <axis xyz="0 -1 -4.37114e-08"/>
  </joint>
  <joint name="LFinger13" type="continuous">
    <parent link="LFinger12Link"/>
    <child link="LFinger13Link"/>
    <origin xyz="0.01436 0 0" rpy="3.71776e-08 0.999899 6.80614e-08"/>
    <axis xyz="0 -1 -4.37114e-08"/>
  </joint>
  <joint name="LFinger21" type="continuous">
    <parent link="LWristYawLink"/>
    <child link="LFinger21Link"/>
    <origin xyz="0.06907 -0.01157 -0.00304" rpy="-0.315405 0.976662 -0.264067"/>
    <axis xyz="0 -0.984808 0.173648"/>
  </joint>
  <joint name="LFinger22" type="continuous">
    <parent link="LFinger21Link"/>
    <child link="LFinger22Link"/>
    <origin xyz="0.01436 0 0" rpy="3.71776e-08 0.999899 6.80614e-08"/>
    <axis xyz="0 -1 -4.37114e-08"/>
  </joint>
  <joint name="LFinger23" type="continuous">
    <parent link="LFinger22Link"/>
    <child link="LFinger23Link"/>
    <origin xyz="0.01436 0 0" rpy="3.71776e-08 0.999899 6.80614e-08"/>
    <axis xyz="0 -1 -4.37114e-08"/>
  </joint>
  <joint name="LThumb1" type="continuous">
    <parent link="LWristYawLink"/>
    <child link="LThumb1Link"/>
    <origin xyz="0.04895 0 -0.02638" rpy="-3.14159 0.0472984 -3.26826e-08"/>
    <axis xyz="3.78552e-08 1 1.09278e-07"/>
  </joint>
  <joint name="LThumb2" type="continuous">
    <parent link="LThumb1Link"/>
    <child link="LThumb2Link"/>
    <origin xyz="0.01436 0 0" rpy="3.71776e-08 0.999899 6.80614e-08"/>
    <axis xyz="0 -1 -4.37114e-08"/>
  </joint>
  <joint name="RShoulderPitch" type="continuous">
    <parent link="TorsoLink"/>
    <child link="RShoulderPitchLink"/>
    <origin xyz="0 -0.098 0.1" rpy="0 -0 0"/>
    <axis xyz="0 1 0"/>
  </joint>
  <joint name="RShoulderRoll" type="continuous">
    <parent link="RShoulderPitchLink"/>
    <child link="RShoulderRollLink"/>
    <origin xyz="0 0 0" rpy="0 -0 0"/>
    <axis xyz="0 0 1"/>
  </joint>
  <joint name="RElbowYaw" type="continuous">
    <parent link="RShoulderRollLink"/>
    <child link="RElbowYawLink"/>
    <origin xyz="0.105 -0.015 0" rpy="0 -0 0"/>
    <axis xyz="1 0 0"/>
  </joint>
  <joint name="RElbowRoll" type="continuous">
    <parent link="RElbowYawLink"/>
    <child link="RElbowRollLink"/>
    <origin xyz="0 0 0" rpy="0 -0 0"/>
    <axis xyz="0 0 1"/>
  </joint>
  <joint name="RWristYaw" type="continuous">
    <parent link="RElbowRollLink"/>
    <child link="RWristYawLink"/>
    <origin xyz="0.05595 0 0" rpy="0 -0 0"/>
    <axis xyz="1 0 0"/>
  </joint>
  <joint name="RFinger11" type="continuous">
    <parent link="RWristYawLink"/>
    <child link="RFinger11Link"/>
    <origin xyz="0.06907 0.01157 -0.00304" rpy="0.315405 0.976662 0.264067"/>
    <axis xyz="0 -0.984808 -0.173648"/>
  </joint>
  <joint name="RFinger12" type="continuous">
    <parent link="RFinger11Link"/>
    <child link="RFinger12Link"/>
    <origin xyz="0.01436 0 0" rpy="3.71776e-08 0.999899 6.80614e-08"/>
    <axis xyz="0 -1 -4.37114e-08"/>
  </joint>
  <joint name="RFinger13" type="continuous">
    <parent link="RFinger12Link"/>
    <child link="RFinger13Link"/>
    <origin xyz="0.01436 0 0" rpy="3.71776e-08 0.999899 6.80614e-08"/>
    <axis xyz="0 -1 -4.37114e-08"/>
  </joint>
  <joint name="RFinger21" type="continuous">
    <parent link="RWristYawLink"/>
    <child link="RFinger21Link"/>
    <origin xyz="0.06907 -0.01157 -0.00304" rpy="-0.315405 0.976662 -0.264067"/>
    <axis xyz="0 -0.984808 0.173648"/>
  </joint>
  <joint name="RFinger22" type="continuous">
    <parent link="RFinger21Link"/>
    <child link="RFinger22Link"/>
    <origin xyz="0.01436 0 0" rpy="3.71776e-08 0.999899 6.80614e-08"/>
    <axis xyz="0 -1 -4.37114e-08"/>
  </joint>
  <joint name="RFinger23" type="continuous">
    <parent link="RFinger22Link"/>
    <child link="RFinger23Link"/>
    <origin xyz="0.01436 0 0" rpy="3.71776e-08 0.999899 6.80614e-08"/>
    <axis xyz="0 -1 -4.37114e-08"/>
  </joint>
  <joint name="RThumb1" type="continuous">
    <parent link="RWristYawLink"/>
    <child link="RThumb1Link"/>
    <origin xyz="0.04895 0 -0.02638" rpy="-3.14159 0.0472984 -3.26826e-08"/>
    <axis xyz="3.78552e-08 1 1.09278e-07"/>
  </joint>
  <joint name="RThumb2" type="continuous">
    <parent link="RThumb1Link"/>
    <child link="RThumb2Link"/>
    <origin xyz="0.01436 0 0" rpy="3.71776e-08 0.999899 6.80614e-08"/>
    <axis xyz="0 -1 -4.37114e-08"/>
  </joint>
  <joint name="LHipYawPitch" type="continuous">
    <parent link="TorsoLink"/>
    <child link="LHipYawPitchLink"/>
    <origin xyz="0 0.05 -0.085" rpy="0 -0 0"/>
    <axis xyz="0 0.707107 -0.707107"/>
  </joint>
  <joint name="LHipRoll" type="continuous">
    <parent link="LHipYawPitchLink"/>
    <child link="LHipRollLink"/>
    <origin xyz="0 0 0" rpy="0 -0 0"/>
    <axis xyz="1 0 0"/>
  </joint>
  <joint name="LHipPitch" type="continuous">
    <parent link="LHipRollLink"/>
    <child link="LHipPitchLink"/>
    <origin xyz="0 0 0" rpy="0 -0 0"/>
    <axis xyz="0 1 0"/>
  </joint>
  <joint name="LKneePitch" type="continuous">
    <parent link="LHipPitchLink"/>
    <child link="LKneePitchLink"/>
    <origin xyz="0 0 -0.1" rpy="0 -0 0"/>
    <axis xyz="0 1 0"/>
  </joint>
  <joint name="LAnklePitch" type="continuous">
    <parent link="LKneePitchLink"/>
    <child link="LAnklePitchLink"/>
    <origin xyz="0 0 -0.1029" rpy="0 -0 0"/>
    <axis xyz="0 1 0"/>
  </joint>
  <joint name="LAnkleRoll" type="continuous">
    <parent link="LAnklePitchLink"/>
    <child link="LAnkleRollLink"/>
    <origin xyz="0 0 0" rpy="0 -0 0"/>
    <axis xyz="1 0 0"/>
  </joint>
  <joint name="RHipYawPitch" type="continuous">
    <parent link="TorsoLink"/>
    <child link="RHipYawPitchLink"/>
    <origin xyz="0 -0.05 -0.085" rpy="0 -0 0"/>
    <axis xyz="0 0.707107 0.707107"/>
  </joint>
  <joint name="RHipRoll" type="continuous">
    <parent link="RHipYawPitchLink"/>
    <child link="RHipRollLink"/>
    <origin xyz="0 0 0" rpy="0 -0 0"/>
    <axis xyz="1 0 0"/>
  </joint>
  <joint name="RHipPitch" type="continuous">
    <parent link="RHipRollLink"/>
    <child link="RHipPitchLink"/>
    <origin xyz="0 0 0" rpy="0 -0 0"/>
    <axis xyz="0 1 0"/>
  </joint>
  <joint name="RKneePitch" type="continuous">
    <parent link="RHipPitchLink"/>
    <child link="RKneePitchLink"/>
    <origin xyz="0 0 -0.1" rpy="0 -0 0"/>
    <axis xyz="0 1 0"/>
  </joint>
  <joint name="RAnklePitch" type="continuous">
    <parent link="RKneePitchLink"/>
    <child link="RAnklePitchLink"/>
    <origin xyz="0 0 -0.1029" rpy="0 -0 0"/>
    <axis xyz="0 1 0"/>
  </joint>
  <joint name="RAnkleRoll" type="continuous">
    <parent link="RAnklePitchLink"/>
    <child link="RAnkleRollLink"/>
    <origin xyz="0 0 0" rpy="0 -0 0"/>
    <axis xyz="1 0 0"/>
  </joint>

  <link name="base_link">
    <visual>
      <geometry>
        <cylinder length="0.01" radius="0.01"/>
      </geometry>
    </visual>
  </link>
  <joint name="base_to_Torso" type="fixed">
    <parent link="base_link"/>
    <child link="TorsoLink"/>
    <origin xyz="0 0 0" rpy="0 0 0"/>
  </joint>
</robot>
